Traceback (most recent call last):
  File "<pyshell#19>", line 2, in <module>
Exception: This is the error message.
Traceback (most recent call last):
  File "<pyshell#21>", line 2, in <module>
Exception: This is the error message.
